Workbook

Sheet Employee_DB
A1: 📋 EMPLOYEE DATABASE
A2: Emp ID | B2: Name | C2: Department | D2: Salary | E2: Join Date | F2: Region | G2: Grade | H2: Status
A3: E001 | B3: Priya Sharma | C3: Sales | D3: 75000 | E3: 2020-03-15 | F3: West | G3: A | H3: Active
A4: E002 | B4: Rahul Mehta | C4: IT | D4: 90000 | E4: 2019-07-22 | F4: North | G4: A+ | H4: Active
A5: E003 | B5: Anjali Singh | C5: HR | D5: 65000 | E5: 2021-01-10 | F5: South | G5: B | H5: Active
A6: E004 | B6: Vikram Nair | C6: Finance | D6: 85000 | E6: 2018-11-30 | F6: East | G6: A | H6: Active
A7: E005 | B7: Sneha Patel | C7: Sales | D7: 70000 | E7: 2022-05-18 | F7: West | G7: B+ | H7: Active
A8: E006 | B8: Arjun Kapoor | C8: IT | D8: 95000 | E8: 2017-09-05 | F8: North | G8: A+ | H8: Active
A9: E007 | B9: Meera Joshi | C9: HR | D9: 62000 | E9: 2023-02-28 | F9: South | G9: B | H9: Active
A10: E008 | B10: Rohit Gupta | C10: Finance | D10: 88000 | E10: 2019-04-14 | F10: East | G10: A | H10: Inactive
A11: E009 | B11: Kavya Reddy | C11: Sales | D11: 72000 | E11: 2021-08-20 | F11: West | G11: B+ | H11: Active
A12: E010 | B12: Suresh Kumar | C12: IT | D12: 98000 | E12: 2016-12-01 | F12: North | G12: A+ | H12: Active

Sheet Sales_Data
A1: 💰 SALES DATA
A2: Month | B2: Region | C2: Product | D2: Salesperson | E2: Units | F2: Revenue
A3: Jan | B3: North | C3: Laptop | D3: Rahul | E3: 45 | F3: 450000
A4: Jan | B4: South | C4: Phone | D4: Anjali | E4: 80 | F4: 240000
A5: Jan | B5: West | C5: Tablet | D5: Priya | E5: 60 | F5: 180000
A6: Feb | B6: North | C6: Laptop | D6: Arjun | E6: 52 | F6: 520000
A7: Feb | B7: East | C7: Phone | D7: Vikram | E7: 90 | F7: 270000
A8: Feb | B8: West | C8: Tablet | D8: Sneha | E8: 70 | F8: 210000
A9: Mar | B9: North | C9: Laptop | D9: Suresh | E9: 48 | F9: 480000
A10: Mar | B10: South | C10: Phone | D10: Meera | E10: 95 | F10: 285000
A11: Mar | B11: East | C11: Tablet | D11: Rohit | E11: 65 | F11: 195000
A12: Apr | B12: West | C12: Laptop | D12: Priya | E12: 55 | F12: 550000
A13: Apr | B13: North | C13: Phone | D13: Rahul | E13: 85 | F13: 255000
A14: Apr | B14: South | C14: Tablet | D14: Anjali | E14: 75 | F14: 225000
... A20: Jun | B20: West | C20: Tablet | D20: Kavya | E20: 72 | F20: 216000

Sheet Formula_Playground
A1: 🔬 ADVANCED EXCEL FORMULA PLAYGROUND
A3: A ▸ LOOKUP FORMULAS
B4: Formula | C4: Description | D4: Result
B5: VLOOKUP | C5: =VLOOKUP("E003",Employee_DB!A3:H12,3,FALSE) | D5: Find Dept of E003
B6: HLOOKUP | C6: =HLOOKUP("Salary",Employee_DB!A2:H12,2,FALSE) | D6: Find 1st Salary row
B7: INDEX | C7: =INDEX(Employee_DB!B3:B12,3) | D7: 3rd Employee Name
B8: MATCH | C8: =MATCH("E005",Employee_DB!A3:A12,0) | D8: Row # of E005
B9: INDEX+MATCH | C9: =INDEX(Employee_DB!B3:B12,MATCH("E007",Employee_DB!A3:A12,0)) | D9: Name for E007
B10: XLOOKUP | C10: =XLOOKUP("E002",Employee_DB!A3:A12,Employee_DB!C3:C12,"Not Found") | D10: Dept of E002
B11: XMATCH | C11: =XMATCH("Finance",Employee_DB!C3:C12) | D11: Finance row #
A13: B ▸ MATH & STATISTICAL FORMULAS
B14: Formula | C14: Description | D14: Result
B15: SUM | C15: =SUM(Employee_DB!D3:D12) | D15: Total Salaries
B16: AVERAGE | C16: =AVERAGE(Employee_DB!D3:D12) | D16: Avg Salary
B17: MAX / MIN | C17: =MAX(Employee_DB!D3:D12) | D17: Highest Salary
B18: COUNT | C18: =COUNT(Employee_DB!D3:D12) | D18: Count of salaries
B19: COUNTA | C19: =COUNTA(Employee_DB!B3:B12) | D19: Non-blank names
B20: SUMIF | C20: =SUMIF(Employee_DB!C3:C12,"IT",Employee_DB!D3:D12) | D20: IT Salaries
B21: AVERAGEIF | C21: =AVERAGEIF(Employee_DB!C3:C12,"Sales",Employee_DB!D3:D12) | D21: Avg Sales Salary
B22: COUNTIF | C22: =COUNTIF(Employee_DB!C3:C12,"Finance") | D22: Finance headcount
B23: SUMIFS | C23: =SUMIFS(Employee_DB!D3:D12,Employee_DB!C3:C12,"IT",Employee_DB!H3:H12,"Active") | D23: Active IT Salaries
B24: COUNTIFS | C24: =COUNTIFS(Employee_DB!C3:C12,"Sales",Employee_DB!H3:H12,"Active") | D24: Active Sales count
B25: RANK | C25: =RANK(Employee_DB!D3,Employee_DB!D3:D12,0) | D25: Rank of 1st salary
B26: LARGE/SMALL | C26: =LARGE(Employee_DB!D3:D12,2) | D26: 2nd Highest Salary
B27: STDEV | C27: =STDEV(Employee_DB!D3:D12) | D27: Salary Std Dev
B28: MEDIAN | C28: =MEDIAN(Employee_DB!D3:D12) | D28: Median Salary
B29: PERCENTILE | C29: =PERCENTILE(Employee_DB!D3:D12,0.75) | D29: 75th Percentile
A31: C ▸ TEXT FORMULAS
B32: Formula | C32: Description | D32: Result
B33: CONCATENATE / & | C33: =Employee_DB!A3&" - "&Employee_DB!B3 | D33: ID + Name joined
B34: TEXTJOIN | C34: =TEXTJOIN(", ",TRUE,Employee_DB!C3:C12) | D34: All departments
B35: LEFT / RIGHT | C35: =LEFT(Employee_DB!B3,5) | D35: First 5 chars of name
B36: MID | C36: =MID(Employee_DB!B4,1,6) | D36: First 6 chars
B37: LEN | C37: =LEN(Employee_DB!B3) | D37: Length of name
B38: UPPER / LOWER | C38: =UPPER(Employee_DB!C3) | D38: Dept in uppercase
B39: TRIM | C39: =TRIM(" Priya Sharma ") | D39: Remove spaces
B40: SUBSTITUTE | C40: =SUBSTITUTE(Employee_DB!B3," ","_") | D40: Space→underscore
B41: FIND | C41: =FIND(" ",Employee_DB!B3) | D41: Position of space
B42: TEXT | C42: =TEXT(Employee_DB!E3,"DD-MMM-YYYY") | D42: Format date as text
B43: VALUE | C43: =VALUE(LEFT(Employee_DB!A3,1)) | D43: Text E→number
...

Sheet Pivot_Dashboard
A1: 📊 PIVOT-STYLE DASHBOARD (SUMIFS / COUNTIFS based)
A3: Revenue by Region | F3: Revenue by Product
A4: Region | B4: Total Revenue | C4: # Deals | D4: Avg Deal Size | F4: Product | G4: Total Revenue | H4: Units Sold | I4: Avg Price/Unit
A5: North | B5: =SUMIF(Sales_Data!B3:B20,A5,Sales_Data!F3:F20) | C5: =COUNTIF(Sales_Data!B3:B20,A5) | D5: =IFERROR(B5/C5,0) | F5: Laptop | G5: =SUMIF(Sales_Data!C3:C20,F5,Sales_Data!F3:F20) | H5: =SUMIF(Sales_Data!C3:C20,F5,Sales_Data!E3:E20) | I5: =IFERROR(G5/H5,0)
A6: South | B6: =SUMIF(Sales_Data!B3:B20,A6,Sales_Data!F3:F20) | C6: =COUNTIF(Sales_Data!B3:B20,A6) | D6: =IFERROR(B6/C6,0) | F6: Phone | G6: =SUMIF(Sales_Data!C3:C20,F6,Sales_Data!F3:F20) | H6: =SUMIF(Sales_Data!C3:C20,F6,Sales_Data!E3:E20) | I6: =IFERROR(G6/H6,0)
A7: East | B7: =SUMIF(Sales_Data!B3:B20,A7,Sales_Data!F3:F20) | C7: =COUNTIF(Sales_Data!B3:B20,A7) | D7: =IFERROR(B7/C7,0) | F7: Tablet | G7: =SUMIF(Sales_Data!C3:C20,F7,Sales_Data!F3:F20) | H7: =SUMIF(Sales_Data!C3:C20,F7,Sales_Data!E3:E20) | I7: =IFERROR(G7/H7,0)
A8: West | B8: =SUMIF(Sales_Data!B3:B20,A8,Sales_Data!F3:F20) | C8: =COUNTIF(Sales_Data!B3:B20,A8) | D8: =IFERROR(B8/C8,0)
A10: Monthly Revenue Summary | F10: Key KPIs
A11: Month | B11: Total Revenue | C11: Deals | D11: % of Total | F11: Total Revenue | G11: =SUM(Sales_Data!F3:F20)
A12: Jan | B12: =SUMIF(Sales_Data!A3:A20,A12,Sales_Data!F3:F20) | C12: =COUNTIF(Sales_Data!A3:A20,A12) | D12: =IFERROR(B12/SUM(B12:B17),0) | F12: Total Units Sold | G12: =SUM(Sales_Data!E3:E20)
A13: Feb | B13: =SUMIF(Sales_Data!A3:A20,A13,Sales_Data!F3:F20) | C13: =COUNTIF(Sales_Data!A3:A20,A13) | D13: =IFERROR(B13/SUM(B12:B17),0) | F13: Avg Revenue/Deal | G13: =AVERAGE(Sales_Data!F3:F20)
A14: Mar | B14: =SUMIF(Sales_Data!A3:A20,A14,Sales_Data!F3:F20) | C14: =COUNTIF(Sales_Data!A3:A20,A14) | D14: =IFERROR(B14/SUM(B12:B17),0) | F14: Max Single Deal | G14: =MAX(Sales_Data!F3:F20)
A15: Apr | B15: =SUMIF(Sales_Data!A3:A20,A15,Sales_Data!F3:F20) | C15: =COUNTIF(Sales_Data!A3:A20,A15) | D15: =IFERROR(B15/SUM(B12:B17),0) | F15: Min Single Deal | G15: =MIN(Sales_Data!F3:F20)
A16: May | B16: =SUMIF(Sales_Data!A3:A20,A16,Sales_Data!F3:F20) | C16: =COUNTIF(Sales_Data!A3:A20,A16) | D16: =IFERROR(B16/SUM(B12:B17),0) | F16: # Transactions | G16: =COUNTA(Sales_Data!A3:A20)
A17: Jun | B17: =SUMIF(Sales_Data!A3:A20,A17,Sales_Data!F3:F20) | C17: =COUNTIF(Sales_Data!A3:A20,A17) | D17: =IFERROR(B17/SUM(B12:B17),0) | F17: Top Region | G17: =INDEX(Sales_Data!B3:B20,MATCH(MAX(Sales_Data!F3:F20),Sales_Data!F3:F20,0))
F18: Top Product | G18: =INDEX(Sales_Data!C3:C20,MATCH(MAX(Sales_Data!F3:F20),Sales_Data!F3:F20,0))

Sheet Array_Advanced
A1: ⚡ ARRAY & ADVANCED FORMULAS
A3: ARRAY FORMULAS
A4: Formula Name | B4: Formula | C4: Description
A5: UNIQUE Depts | B5: =UNIQUE(Employee_DB!C3:C12) | C5: Distinct dept list
A6: SORT by Salary | B6: =SORT(Employee_DB!D3:D12,1,-1) | C6: Salaries desc order
A7: FILTER Active | B7: =FILTER(Employee_DB!B3:B12,Employee_DB!H3:H12="Active","None") | C7: Active emp names
A8: SEQUENCE 1-10 | B8: =SEQUENCE(10) | C8: Numbers 1 to 10
A10: FINANCIAL FORMULAS
A11: Formula Name | B11: Formula | C11: Description
A12: PMT (Loan EMI) | B12: =PMT(8%/12,60,500000) | C12: ₹5L loan 5yr @8%
A13: FV (Future Value) | B13: =FV(12%/12,120,-5000,0) | C13: SIP FV 10yr @12%
A14: NPV | B14: =NPV(10%,50000,60000,70000,80000) | C14: NPV @10% disc rate
A15: IRR | B15: =IRR({-100000,30000,40000,50000,60000}) | C15: IRR of cash flows
A16: PV (Present Value) | B16: =PV(8%/12,60,10000) | C16: PV of ₹10k/mo 5yr
A18: DYNAMIC ARRAY / MISC
A19: Formula Name | B19: Formula | C19: Description
A20: TRANSPOSE | B20: =TRANSPOSE(Employee_DB!A2:C2) | C20: Flip row to column
A21: FREQUENCY | B21: =FREQUENCY(Employee_DB!D3:D12,{65000,75000,90000}) | C21: Salary distribution
A22: MMULT | B22: =MMULT({1,2,3},{4;5;6}) | C22: Matrix multiply
A23: LET (Named vars) | B23: =LET(sal,Employee_DB!D3:D12,avg,AVERAGE(sal),COUNTIF(sal,">"&avg)) | C23: Above avg count
A24: LAMBDA concept | B24: =MAP(Employee_DB!D3:D5,LAMBDA(x,x*1.1)) | C24: 10% raise for top 3

Sheet How_To_Guide
A1: 📖 HOW TO USE THIS WORKBOOK
A3: SHEET | B3: WHAT IT CONTAINS | C3: HOW TO USE
A4: Employee_DB | B4: 10 sample employees with ID, name, dept, salary, join date, region, grade, status | C4: Source data for VLOOKUP, XLOOKUP, INDEX-MATCH. Add/edit rows to see formulas update.
A5: Sales_Data | B5: 18 sales transactions across 6 months, 4 regions, 3 products | C5: Source data for SUMIF/COUNTIF pivot tables in Dashboard sheet.
A6: Formula_Playground | B6: 5 sections (A–E) covering 60+ formulas: Lookups, Math, Text, Date, Logic | C6: Each row shows formula name → formula text (purple) → description. Study & copy formulas.
A7: Pivot_Dashboard | B7: SUMIFS/COUNTIFS-based pivot tables: by Region, Product, Month + KPI panel | C7: Demonstrates how to summarize data without using Pivot Table UI. Change source data to refresh.
A8: Array_Advanced | B8: Array formulas (UNIQUE, FILTER, SORT), Financial (PMT, FV, NPV, IRR), LET, LAMBDA | C8: Advanced formulas for modern Excel (365/2021). Some require Ctrl+Shift+Enter in older versions.
A9: How_To_Guide | B9: This instruction sheet | C9: Reference guide on formula usage and sheet structure.
A12: 11
A13: F2 Key | B13: Enter cell edit mode to see formula references highlighted in color.
A14: F4 Key | B14: Toggle between relative/absolute references (A1 → $A$1 → A$1 → $A1).
A15: Ctrl+` | B15: Toggle Show Formulas mode to see all formulas at once.
A16: Ctrl+Shift+Enter | B16: Required for array formulas in Excel 2019 and older.
A17: Name Manager | B17: Formulas → Name Manager — create named ranges for cleaner formulas.
A18: Evaluate Formula | B18: Formulas → Evaluate Formula — step through complex formula logic.
A19: Watch Window | B19: Formulas → Watch Window — monitor key cells while scrolling.
A20: Error Checking | B20: Formulas → Error Checking — auto-detect formula issues.
A21: IFERROR Wrapper | B21: Wrap any risky formula: =IFERROR(your_formula, 'Error') for cleaner output.
A22: Absolute Refs | B22: Use $A$1 in SUMIF/VLOOKUP ranges to safely copy formulas down/across.
